Workbook

Sheet 안내
A1: 아파트 셀프 사전점검 체크리스트
A2: 작성일 2026-10-08 · 매부리TV 「신축 아파트 사전점검 A부터 Z까지」 4단계 구성(점검 순서 → 준비물 → 장소별 핵심 → 하자 대응) 기준
A4: 시트 구성
A5: 준비물 | B5: 가기 전에 챙길 것. 챙기면 B열에 ○ 선택
A6: 점검표 | B6: 공간별 점검 항목. 노란 칸(결과·하자번호·위치/메모)만 입력하세요
A7: 하자기록 | B7: 하자를 찾으면 한 줄씩 기록. K열 문구를 복사해 더샵 앱에 붙여넣기
A8: 더샵 사전방문 | B8: 포스코이앤씨 더샵 사전방문 예약부터 휴대폰 접수, 보수 확인까지 순서
A9: 요약 | B9: 공간별 진행률과 하자 개수가 자동 계산됩니다 (입력 불필요)
A10: 참고영상 | B10: 참고한 YouTube 영상과 자료
A12: 결과 입력 방법
A13: ○ | B13: 이상 없음
A14: ✖ | B14: 하자 있음 → 하자번호를 적고 하자기록 시트에 상세 기록
A15: △ | B15: 애매함 → 나중에 다시 확인
A17: 점검 순서 | B17: 현관에서 시작해 시계 방향으로. 공간마다 문 → 천장 → 창 → 벽 → 바닥 → 작동 테스트
A18: 사진 원칙 | B18: 원거리 1장(위치) + 근접 1장(하자). 배수·소음은 동영상
A19: 접수 | B19: 당일 시공사 앱으로 접수 후 화면 캡처. 앱 오류 시 현장 본부에 서면 하자보수 요청서 제출
A20: 셀프 한계 | B20: 열화상(단열·결로), 라돈·공기질, 콘센트 접지, 매립 배관 누수는 장비 필요
A22: 주의 | B22: 영상의 구성은 썸네일로 확인했으나 영상 속 세부 발언은 확인하지 못했습니다. 세부 항목은 여러 사전점검 가이드 자료로 채웠습니다.

Sheet 준비물
A1: 준비물 | B1: 챙김 | C1: 메모
A2: 신분증, 사전점검 초대장(안내문)
A3: 분양계약서 / 옵션 계약서 (옵션 반영 확인용)
A4: 이 체크리스트 출력본 또는 점검 앱 (시공사 하자접수 앱 미리 설치)
A5: 스마트폰 + 보조배터리 (사진·영상)
A6: 휴대폰 충전기 또는 콘센트 테스터 (콘센트 통전 확인)
A7: 손전등 (빛 각도로 도배·바닥 확인)
A8: 수평계 또는 수평계 앱, 줄자
A9: 고무망치 또는 단단한 펜 (타일 타격)
A10: 바가지·대야, 물 1~2병 (배수·구배 확인)
A11: 마스킹테이프·하자 스티커·포스트잇, 네임펜
A12: 작은 거울 (싱크대·세면대 하부, 문 윗면 확인)
A13: 목장갑, 일회용 슬리퍼 또는 덧신, 마스크(분진), 물티슈
... A17: (선택) 돗자리 — 바닥에 앉아 정리할 때
A19: 챙긴 개수 | B19: =COUNTIF(B2:B17,"○")&"/"&COUNTA(A2:A17)

Sheet 점검표
A1: No | B1: 공간 | C1: 구분 | D1: 점검 항목 | E1: 결과 | F1: 하자번호 | G1: 위치 / 메모
A2: 1 | B2: 현관 / 복도 | D2: 현관문 개폐가 부드러운지, 도어클로저 속도, 닫힐 때 소음
A3: 2 | B3: 현관 / 복도 | D3: 현관문 표면 찍힘·도장 손상, 문틀과의 틈
A4: 3 | B4: 현관 / 복도 | D4: 도어록 작동(비밀번호·카드·기계식 열쇠), 말발굽(도어스토퍼)
A5: 4 | B5: 현관 / 복도 | D5: 현관 바닥 타일·대리석 깨짐, 들뜸(타격), 줄눈
A6: 5 | B6: 현관 / 복도 | D6: 신발장 문 수평과 간격, 경첩, 내부 선반, 마감 상태
A7: 6 | B7: 현관 / 복도 | D7: 센서등 작동
A8: 7 | B8: 현관 / 복도 | D8: 중문(옵션) 설치 상태와 개폐
A9: 8 | B9: 거실 / 침실 | C9: 천장·벽 | D9: 천장 도배 울음·얼룩, 조명·스프링클러·감지기 주변 마감
A10: 9 | B10: 거실 / 침실 | C10: 천장·벽 | D10: 벽지 들뜸, 이음매 벌어짐, 오염, 찢김 (손전등을 비스듬히 비춰서)
A11: 10 | B11: 거실 / 침실 | C11: 천장·벽 | D11: 몰딩·걸레받이 벌어짐, 틈, 찍힘
A12: 11 | B12: 거실 / 침실 | C12: 천장·벽 | D12: 벽 모서리(특히 외벽 쪽) 곰팡이·습기 흔적
A13: 12 | B13: 거실 / 침실 | C13: 바닥 | D13: 마루 찍힘·스크래치·들뜸, 걸을 때 삐걱 소리
A14: 13 | B14: 거실 / 침실 | C14: 바닥 | D14: 바닥 수평 (수평계·구슬 굴려 보기)
A15: 14 | B15: 거실 / 침실 | C15: 바닥 | D15: 마루와 걸레받이·문턱 사이 틈
A16: 15 | B16: 거실 / 침실 | C16: 문·창호 | D16: 방문 개폐, 처짐, 문틀 수직, 손잡이·잠금
A17: 16 | B17: 거실 / 침실 | C17: 문·창호 | D17: 창문 3회 이상 여닫기 — 걸림, 소음, 잠금장치(크레센트) 작동
A18: 17 | B18: 거실 / 침실 | C18: 문·창호 | D18: 창틀 실리콘 끊김, 유리 스크래치·금, 방충망 찢김·개폐
A19: 18 | B19: 거실 / 침실 | C19: 문·창호 | D19: 창틀 하부 배수구멍 막힘 여부
A20: 19 | B20: 거실 / 침실 | C20: 전기·설비 | D20: 모든 스위치 ON/OFF, 조명 깜빡임
... A24: 23 | B24: 거실 / 침실 | C24: 전기·설비 | D24: 에어컨 배관 슬리브·매립 배관 위치 (옵션 계약과 대조)
A25: 24 | B25: 주방 | D25: 상부장·하부장 문 수평과 간격, 경첩, 서랍 레일
A26: 25 | B26: 주방 | D26: 상판 스크래치·깨짐, 상판과 벽 사이 실리콘
A27: 26 | B27: 주방 | D27: 싱크볼 스크래치, 수전 냉·온수, 수압
A28: 27 | B28: 주방 | D28: 물을 틀어 놓고 싱크대 하부 배관 누수 확인 (손전등 + 거울)
A29: 28 | B29: 주방 | D29: 배수 속도, 배수구 냄새
A30: 29 | B30: 주방 | D30: 쿡탑·후드(흡입·조명) 작동, 후드 덕트 연결
A31: 30 | B31: 주방 | D31: 빌트인 가전(식세기·오븐·냉장고장) 작동 — 옵션 계약과 대조
A32: 31 | B32: 주방 | D32: 주방 벽 타일 들뜸(타격)·줄눈·깨짐
A33: 32 | B33: 주방 | D33: 가스 배관·밸브 (가스 공급 전이면 위치만 확인)
A34: 33 | B34: 욕실 | C34: 타일·실리콘 | D34: 벽·바닥 타일 타격 점검 — 빈 소리(텅텅) 나면 들뜸
A35: 34 | B35: 욕실 | C35: 타일·실리콘 | D35: 타일 깨짐, 단차(손으로 쓸어 보기), 줄눈 빠짐
A36: 35 | B36: 욕실 | C36: 타일·실리콘 | D36: 세면대·욕조·샤워부스·변기 주변 실리콘 빈 곳, 끊김
A37: 36 | B37: 욕실 | C37: 배수·구배 | D37: 바닥에 바가지로 물을 부어 배수구 방향으로 흐르는지, 고이는 곳이 없는지 (영상으로 기록)
A38: 37 | B38: 욕실 | C38: 배수·구배 | D38: 세면대·욕조·샤워 배수 속도
A39: 38 | B39: 욕실 | C39: 배수·구배 | D39: 욕실 문턱 밖으로 물이 넘치지 않는지
A40: 39 | B40: 욕실 | C40: 위생기구·수전 | D40: 변기 흔들림, 물 내림, 물 멈춤, 변기 하부 누수
A41: 40 | B41: 욕실 | C41: 위생기구·수전 | D41: 세면대 고정(눌러 보기), 하부 배관 누수
A42: 41 | B42: 욕실 | C42: 위생기구·수전 | D42: 수전 냉·온수 방향, 수압, 샤워헤드·해바라기 전환
A43: 42 | B43: 욕실 | C43: 위생기구·수전 | D43: 샤워부스 유리 고정, 문 개폐, 하부 물막이
...

Sheet 하자기록
A1: 하자번호 | B1: 공간 | C1: 위치(구체적으로) | D1: 증상 | E1: 사진 | F1: 접수일 | G1: 접수 방법 | H1: 보수 예정일 | I1: 보수 완료 확인 | J1: 비고 | K1: 앱 접수 문구 (자동 · 복사해서 붙여넣기)
A2: 예시) 1 | B2: 욕실 | C2: 안방 욕실 바닥, 배수구 왼쪽 30cm | D2: 물 부으면 배수구 반대편에 고임 (영상 촬영) | E2: ○ | F2: 46303 | G2: 더샵 앱/웹 | H2: 46341 | I2: 미완료 | J2: 이 줄은 예시입니다. 지우고 쓰세요 | K2: =IF(C2="","",B2&" / "&C2&" : "&D2)
A3: 1 | K3: =IF(C3="","",B3&" / "&C3&" : "&D3)
A4: 2 | K4: =IF(C4="","",B4&" / "&C4&" : "&D4)
A5: 3 | K5: =IF(C5="","",B5&" / "&C5&" : "&D5)
A6: 4 | K6: =IF(C6="","",B6&" / "&C6&" : "&D6)
A7: 5 | K7: =IF(C7="","",B7&" / "&C7&" : "&D7)
A8: 6 | K8: =IF(C8="","",B8&" / "&C8&" : "&D8)
A9: 7 | K9: =IF(C9="","",B9&" / "&C9&" : "&D9)
A10: 8 | K10: =IF(C10="","",B10&" / "&C10&" : "&D10)
A11: 9 | K11: =IF(C11="","",B11&" / "&C11&" : "&D11)
A12: 10 | K12: =IF(C12="","",B12&" / "&C12&" : "&D12)
A13: 11 | K13: =IF(C13="","",B13&" / "&C13&" : "&D13)
A14: 12 | K14: =IF(C14="","",B14&" / "&C14&" : "&D14)
... A101: 99 | K101: =IF(C101="","",B101&" / "&C101&" : "&D101)

Sheet 요약
A1: 공간 | B1: 항목 수 | C1: 점검 완료 | D1: 진행률 | E1: ○ 이상없음 | F1: ✖ 하자 | G1: △ 재확인 | H1: 하자기록 수 | I1: 보수 완료
A2: 현관 / 복도 | B2: =COUNTIF(점검표!$B$2:$B$62,A2) | C2: =COUNTIFS(점검표!$B$2:$B$62,A2,점검표!$E$2:$E$62,"<>") | D2: =IF(B2=0,0,C2/B2) | E2: =COUNTIFS(점검표!$B$2:$B$62,A2,점검표!$E$2:$E$62,"○") | F2: =COUNTIFS(점검표!$B$2:$B$62,A2,점검표!$E$2:$E$62,"✖") | G2: =COUNTIFS(점검표!$B$2:$B$62,A2,점검표!$E$2:$E$62,"△") | H2: =COUNTIF(하자기록!$B$3:$B$101,A2) | I2: =COUNTIFS(하자기록!$B$3:$B$101,A2,하자기록!$I$3:$I$101,"완료")
A3: 거실 / 침실 | B3: =COUNTIF(점검표!$B$2:$B$62,A3) | C3: =COUNTIFS(점검표!$B$2:$B$62,A3,점검표!$E$2:$E$62,"<>") | D3: =IF(B3=0,0,C3/B3) | E3: =COUNTIFS(점검표!$B$2:$B$62,A3,점검표!$E$2:$E$62,"○") | F3: =COUNTIFS(점검표!$B$2:$B$62,A3,점검표!$E$2:$E$62,"✖") | G3: =COUNTIFS(점검표!$B$2:$B$62,A3,점검표!$E$2:$E$62,"△") | H3: =COUNTIF(하자기록!$B$3:$B$101,A3) | I3: =COUNTIFS(하자기록!$B$3:$B$101,A3,하자기록!$I$3:$I$101,"완료")
A4: 주방 | B4: =COUNTIF(점검표!$B$2:$B$62,A4) | C4: =COUNTIFS(점검표!$B$2:$B$62,A4,점검표!$E$2:$E$62,"<>") | D4: =IF(B4=0,0,C4/B4) | E4: =COUNTIFS(점검표!$B$2:$B$62,A4,점검표!$E$2:$E$62,"○") | F4: =COUNTIFS(점검표!$B$2:$B$62,A4,점검표!$E$2:$E$62,"✖") | G4: =COUNTIFS(점검표!$B$2:$B$62,A4,점검표!$E$2:$E$62,"△") | H4: =COUNTIF(하자기록!$B$3:$B$101,A4) | I4: =COUNTIFS(하자기록!$B$3:$B$101,A4,하자기록!$I$3:$I$101,"완료")
A5: 욕실 | B5: =COUNTIF(점검표!$B$2:$B$62,A5) | C5: =COUNTIFS(점검표!$B$2:$B$62,A5,점검표!$E$2:$E$62,"<>") | D5: =IF(B5=0,0,C5/B5) | E5: =COUNTIFS(점검표!$B$2:$B$62,A5,점검표!$E$2:$E$62,"○") | F5: =COUNTIFS(점검표!$B$2:$B$62,A5,점검표!$E$2:$E$62,"✖") | G5: =COUNTIFS(점검표!$B$2:$B$62,A5,점검표!$E$2:$E$62,"△") | H5: =COUNTIF(하자기록!$B$3:$B$101,A5) | I5: =COUNTIFS(하자기록!$B$3:$B$101,A5,하자기록!$I$3:$I$101,"완료")
A6: 발코니 / 다용도실 / 실외기실 | B6: =COUNTIF(점검표!$B$2:$B$62,A6) | C6: =COUNTIFS(점검표!$B$2:$B$62,A6,점검표!$E$2:$E$62,"<>") | D6: =IF(B6=0,0,C6/B6) | E6: =COUNTIFS(점검표!$B$2:$B$62,A6,점검표!$E$2:$E$62,"○") | F6: =COUNTIFS(점검표!$B$2:$B$62,A6,점검표!$E$2:$E$62,"✖") | G6: =COUNTIFS(점검표!$B$2:$B$62,A6,점검표!$E$2:$E$62,"△") | H6: =COUNTIF(하자기록!$B$3:$B$101,A6) | I6: =COUNTIFS(하자기록!$B$3:$B$101,A6,하자기록!$I$3:$I$101,"완료")
A7: 드레스룸 / 팬트리 / 수납 | B7: =COUNTIF(점검표!$B$2:$B$62,A7) | C7: =COUNTIFS(점검표!$B$2:$B$62,A7,점검표!$E$2:$E$62,"<>") | D7: =IF(B7=0,0,C7/B7) | E7: =COUNTIFS(점검표!$B$2:$B$62,A7,점검표!$E$2:$E$62,"○") | F7: =COUNTIFS(점검표!$B$2:$B$62,A7,점검표!$E$2:$E$62,"✖") | G7: =COUNTIFS(점검표!$B$2:$B$62,A7,점검표!$E$2:$E$62,"△") | H7: =COUNTIF(하자기록!$B$3:$B$101,A7) | I7: =COUNTIFS(하자기록!$B$3:$B$101,A7,하자기록!$I$3:$I$101,"완료")
A8: 공용·설비 | B8: =COUNTIF(점검표!$B$2:$B$62,A8) | C8: =COUNTIFS(점검표!$B$2:$B$62,A8,점검표!$E$2:$E$62,"<>") | D8: =IF(B8=0,0,C8/B8) | E8: =COUNTIFS(점검표!$B$2:$B$62,A8,점검표!$E$2:$E$62,"○") | F8: =COUNTIFS(점검표!$B$2:$B$62,A8,점검표!$E$2:$E$62,"✖") | G8: =COUNTIFS(점검표!$B$2:$B$62,A8,점검표!$E$2:$E$62,"△") | H8: =COUNTIF(하자기록!$B$3:$B$101,A8) | I8: =COUNTIFS(하자기록!$B$3:$B$101,A8,하자기록!$I$3:$I$101,"완료")
A9: 합계 | B9: =SUM(B2:B8) | C9: =SUM(C2:C8) | D9: =IF(B9=0,0,C9/B9) | E9: =SUM(E2:E8) | F9: =SUM(F2:F8) | G9: =SUM(G2:G8) | H9: =SUM(H2:H8) | I9: =SUM(I2:I8)
A11: ※ 하자기록 수는 2행 예시를 제외하고 셉니다.

Sheet 더샵 사전방문
A1: 포스코이앤씨 더샵 사전방문(사전점검) · 휴대폰 하자 접수 순서
A2: ※ 단지마다 앱 이름·접수 방식·기한이 다릅니다. 노란 칸은 받으신 사전방문 안내문(문자·우편)을 보고 채우세요.
A4: 기본 정보
B5: 단지명
B6: 사전방문 일시 (예약한 날짜·시간)
B7: 하자 접수 앱/웹 이름·주소 (안내문 기재)
B8: 앱 로그인 정보 (계약자명·동호수)
B9: 하자 접수 마감 일시
B10: 입주지원센터 연락처
B11: 보수 확인 재방문 일정
A13: 진행 순서
A14: 단계 | B14: 할 일 | C14: 완료 | D14: 메모
A15: 사전 | B15: 안내문(문자·우편)에서 방문 예약 → 날짜·시간 확정
A16: 사전 | B16: 단지 지정 하자 접수 앱/웹을 미리 설치하고 로그인 확인 (계약자 정보·동호수 입력)
A17: 사전 | B17: 방문 전날 받은 입장 QR코드(단지에 따라 발송) 캡처해 두기
A18: 사전 | B18: 휴대폰 충전, 보조배터리, 저장공간 확보 (사진이 많음)
A19: 당일 | B19: 입주지원센터(접수처)에서 QR·신분증 확인 → 교육 듣기 → 점검표·스티커 받기
A20: 당일 | B20: 현관부터 시계 방향으로 점검 (점검표 시트 순서대로)
A21: 당일 | B21: 하자 발견 → 스티커 부착 → 사진(원거리+근접) → 하자기록 시트에 기록
A22: 당일 | B22: 휴대폰 앱/웹에 하자 등록: 공간 선택 → 사진 첨부 → 위치·증상 입력 (하자기록 K열 문구 복사)
A23: 당일 | B23: 나가기 전 접수 목록 화면을 캡처하고, 하자기록과 개수 맞춰 보기
A24: 기한 내 | B24: 집에서 사진을 다시 보며 빠진 하자 추가 등록 (접수 마감 전까지)
A25: 이후 | B25: 앱에서 처리 상태(접수 → 보수 중 → 완료) 확인
A26: 이후 | B26: 보수 확인 재방문 때 하자번호별로 완료 확인 → 하자기록 I열 갱신
A27: 이후 | B27: 앱에 안 되는 건은 입주지원센터에 서면 요청서 제출, 입주 후에는 관리사무소·하자보수 기간 내 접수
A29: 하자로 잘못 접수하기 쉬운 것 (현장 확인 후 판단)
B30: · 현관 방화문에 말발굽(도어스토퍼)이 없는 것 — 방화문은 닫힌 상태가 원칙이라 기본 미설치인 경우가 많음
B31: · 목문틀의 타카핀 자국 — 시공 방식상 생기는 자국
B32: · 줄눈 없는(무메지) 아트월 타일 — 설계상 줄눈이 없는 마감
B33: · 계약하지 않은 옵션이 없는 것 — 분양·옵션 계약서와 대조
B35: 출처: 광명 자이 더샵 포레나 사전점검 가이드(xi-guide.oopy.io), 사전점검 앱 공통 접수 흐름 자료. 더샵 공식 절차는 단지 안내문이 우선입니다.

Sheet 참고영상
A1: # | B1: 영상 / 자료 | C1: 채널 | D1: 정보 | E1: 핵심
A2: 1 | B2: 신축 아파트 사전점검 A부터 Z까지 | C2: 매부리TV | D2: 28:52 · 조회수 50만 · 2년 전 | E2: 점검 순서·준비물·장소별 핵심·하자 대응 4부 구성 (이 체크리스트의 기준)
A3: 2 | B3: 신축아파트 셀프사전점검 꼭 확인해야하는 72가지 체크리스트 | C3: 오늘의청소 | D3: 16:23 · 조회수 2.7만 · 4개월 전 | E3: 업체 노하우. 댓글 이벤트로 72항목 체크리스트표 제공
A4: 3 | B4: 신축 하자 점검, 사전 체크 셀프로 하는 방법 | C4: @ShinBBBB | D4: 3년 전 | E4: 개인 셀프 점검 영상
A5: 4 | B5: 아파트 셀프 사전 점검 / 체크리스트, 업체, 준비물, 시간 등 꿀팁 모음집 | C5: 판교팬칠칠이_아파트TV | D5: youtube.com/watch?v=pHY_XkgKvBA | E5: 준비물, 소요 시간, 셀프 vs 업체
A6: 5 | B6: 신축아파트 셀프 사전점검 이영상 하나로 끝내세요 | C6: - | D6: youtube.com/watch?v=OGMj0T7GBjI | E6: 공간별 점검 꿀팁
A7: 6 | B7: 아파트 사전점검 7가지 체크리스트 셀프 하자점검 | C7: 라르고 | D7: youtube.com/watch?v=cYHDBCUOnbc | E7: 창호·욕실·주방·콘센트·도배
B9: ※ 영상 자막은 확인하지 못했습니다(YouTube가 서버 접속 차단). 세부 항목은 홈체크, 월부, 오늘의집, 뉴라부동산 등의 가이드 자료로 보완했습니다.

Sheet _목록
A1: 현관 / 복도
A2: 거실 / 침실
A3: 주방
A4: 욕실
A5: 발코니 / 다용도실 / 실외기실
A6: 드레스룸 / 팬트리 / 수납
A7: 공용·설비
